<robot name="test_robot">

  <link name="base_link">
    <inertial>
      <mass value="1"/>
      <inertia ixx="0.00226666666666667" ixy="0" ixz="0" iyy="0.00734166666666667" iyz="0" izz="0.00534166666666667"/>
    </inertial>
    <visual>
      <origin rpy="0 0 0" xyz="--0.05 0 0.085"/>
      <geometry>
        <box size="0.25 0.16 0.04"/>
      </geometry>
      <material name="grey888">
        <color rgba=".8 .8 .8 1"/>
      </material>
    </visual>
    <collision>
      <origin rpy="0 0 0" xyz="--0.05 0 0.085"/>
      <geometry>
        <box size="0.25 0.16 0.04"/>
      </geometry>
      <material name="blue">
        <color rgba=".2 .2 1 1"/>
      </material>
    </collision>
  </link>
  
  <link name="lwheel">
    <visual>
      <geometry>
        <cylinder length="0.01" radius="0.046"/>
      </geometry>
      <origin rpy="0 -1.5707963 0" xyz="0 0 0"/>
      <material name="black112">
        <color rgba=".1 .1 .2 1"/>
      </material>
    </visual>
    <collision>
      <geometry>
        <cylinder length="0.01" radius="0.046"/>
      </geometry>
      <origin rpy="0 -1.5707963 0" xyz="0 0 0"/>
      <material name="black">
        <color rgba="0 0 0 1"/>
      </material>
    </collision>
  </link>

  <link name="lwheel_mark">
    <visual>
      <origin rpy="0 0 0" xyz="0 0 0.02"/>
      <geometry>
        <box size="0.01 0.02 0.03"/>
      </geometry>
      <material name="blue339">
        <color rgba=".3 .3 1 1"/>
      </material>
    </visual>
  </link>

  <joint name="lwheel_to_lwheel_mark" type="fixed">
    <parent link="lwheel"/>
    <child link="lwheel_mark"/>
    <origin xyz="0 0 0" rpy="0 0 1.5707963"/>
  </joint>

  <joint name="base_to_lwheel" type="continuous">
    <parent link="base_link"/>
    <child link="lwheel"/>
    <axis xyz="-1 0 0"/>
    <origin xyz="-0.05 0.115 0.046" rpy="0 0 1.5707963"/>
  </joint>
  
  <link name="rwheel">
    <visual>
      <geometry>
        <cylinder length="0.01" radius="0.046"/>
      </geometry>
      <origin rpy="0 1.5707963 0" xyz="0 0 0"/>
      <material name="black131">
        <color rgba=".1 .3 .1 1"/>
      </material>
    </visual>
    <collision>
      <geometry>
        <cylinder length="0.01" radius="0.046"/>
      </geometry>
      <origin rpy="0 1.5707963 0" xyz="0 0 0"/>
      <material name="black">
        <color rgba="0 0 0 1"/>
      </material>
    </collision>
  </link>
  
  <joint name="base_to_rwheel" type="continuous">
    <parent link="base_link"/>
    <child link="rwheel"/>
    <axis xyz="1 0 0"/>
    <origin xyz="-0.05 -0.115 0.046" rpy="0 0 -1.5707963"/>
  </joint>
  
  <link name="rwheel_mark">
    <visual>
      <origin rpy="0 0 0" xyz="0 0 0.02"/>
      <geometry>
        <box size="0.01 0.02 0.03"/>
      </geometry>
      <material name="green">
        <color rgba="0 1 0 1"/>
      </material>
    </visual>
  </link>

  <joint name="rwheel_to_rwheel_mark" type="fixed">
    <parent link="rwheel"/>
    <child link="rwheel_mark"/>
    <origin xyz="0 0 0" rpy="0 0 -1.5707963"/>
  </joint>

  <link name="fwheel_attach">
    <visual>
      <geometry>
        <cylinder length="0.060" radius="0.023"/>
      </geometry>
      <origin rpy="0 0 0" xyz="0.13 0 0.08"/>
      <material name="white388">
        <color rgba=".3 .8 .8 1"/>
      </material>
    </visual>
    <collision>
      <geometry>
        <cylinder length="0.060" radius="0.023"/>
      </geometry>
      <origin rpy="0 0 0" xyz="0.13 0 0.08"/>
    </collision>
  </link>
  
  <joint name="base_to_fattach" type="fixed">
    <parent link="base_link"/>
    <child link="fwheel_attach"/>
    <origin xyz="0 0 0" rpy="0 0 0"/>
  </joint>
  
  <link name="fwheel">
    <visual>
      <geometry>
        <cylinder length="0.005" radius="0.020"/>
      </geometry>
      <origin rpy="1.5707963 0 0" xyz="0 0 0"/>
      <material name="black">
        <color rgba="0 0 0 1"/>
      </material>
    </visual>
    <collision>
      <geometry>
        <cylinder length="0.005" radius="0.020"/>
      </geometry>
      <origin rpy="1.5707963 0 0" xyz="0 0 0"/>
      <material name="black">
        <color rgba="0 0 0 1"/>
      </material>
    </collision>
  </link>
  
  <joint name="base_to_fwheel" type="fixed">
    <parent link="base_link"/>
    <child link="fwheel"/>
    <origin xyz="0.13 0 0.02" rpy="0 0 0"/>
  </joint>
  
  <link name="scanner">
    <visual>
      <geometry>
        <box size="0.015 0.045 0.015"/>
      </geometry>
      <origin rpy="0 0 0" xyz="0.022 0 0.01"/>
      <material name="red122">
        <color rgba="1 .2 .2 1"/>
      </material>
    </visual>
  </link>
  
  <joint name="base_to_scanner" type="fixed">
    <parent link="base_link"/>
    <child link="scanner"/>
    <origin xyz="0.105 0 0.12" rpy="0 0 0"/>
  </joint>
  
</robot>
